Traceback (most recent call last):
  File "/opt/hostedtoolcache/Python/3.8.17/x64/lib/python3.8/site-packages/jupyter_cache/executors/utils.py", line 58, in single_nb_execution
    executenb(
  File "/opt/hostedtoolcache/Python/3.8.17/x64/lib/python3.8/site-packages/nbclient/client.py", line 1305, in execute
    return NotebookClient(nb=nb, resources=resources, km=km, **kwargs).execute()
  File "/opt/hostedtoolcache/Python/3.8.17/x64/lib/python3.8/site-packages/jupyter_core/utils/__init__.py", line 166, in wrapped
    return loop.run_until_complete(inner)
  File "/opt/hostedtoolcache/Python/3.8.17/x64/lib/python3.8/asyncio/base_events.py", line 616, in run_until_complete
    return future.result()
  File "/opt/hostedtoolcache/Python/3.8.17/x64/lib/python3.8/site-packages/nbclient/client.py", line 705, in async_execute
    await self.async_execute_cell(
  File "/opt/hostedtoolcache/Python/3.8.17/x64/lib/python3.8/site-packages/nbclient/client.py", line 1058, in async_execute_cell
    await self._check_raise_for_error(cell, cell_index, exec_reply)
  File "/opt/hostedtoolcache/Python/3.8.17/x64/lib/python3.8/site-packages/nbclient/client.py", line 914, in _check_raise_for_error
    raise CellExecutionError.from_cell_and_msg(cell, exec_reply_content)
nbclient.exceptions.CellExecutionError: An error occurred while executing the following cell:
------------------
out = ps.simulations.tortuosity_gdd(im, scale_factor=3)
out[:3]
------------------

----- stdout -----
Max distance transform found: 9.164999961853027
[3 3 3] <= [3,3,3], using 33 as chunk size.
------------------

[0;31m---------------------------------------------------------------------------[0m
[0;31mTypeError[0m                                 Traceback (most recent call last)
Cell [0;32mIn[3], line 2[0m
[1;32m      1[0m out [38;5;241m=[39m ps[38;5;241m.[39msimulations[38;5;241m.[39mtortuosity_gdd(im, scale_factor[38;5;241m=[39m[38;5;241m3[39m)
[0;32m----> 2[0m [43mout[49m[43m[[49m[43m:[49m[38;5;241;43m3[39;49m[43m][49m

File [0;32m~/work/porespy/porespy/porespy/tools/_utils.py:323[0m, in [0;36mResults.__getitem__[0;34m(self, key)[0m
[1;32m    322[0m [38;5;28;01mdef[39;00m [38;5;21m__getitem__[39m([38;5;28mself[39m, key):
[0;32m--> 323[0m     [38;5;28;01mreturn[39;00m [38;5;28;43mgetattr[39;49m[43m([49m[38;5;28;43mself[39;49m[43m,[49m[43m [49m[43mkey[49m[43m)[49m

[0;31mTypeError[0m: getattr(): attribute name must be string

