Traceback (most recent call last):
  File "/opt/hostedtoolcache/Python/3.8.17/x64/lib/python3.8/site-packages/nbclient/client.py", line 778, in _async_poll_for_reply
    msg = await ensure_async(self.kc.shell_channel.get_msg(timeout=new_timeout))
  File "/opt/hostedtoolcache/Python/3.8.17/x64/lib/python3.8/site-packages/jupyter_core/utils/__init__.py", line 182, in ensure_async
    result = await obj
  File "/opt/hostedtoolcache/Python/3.8.17/x64/lib/python3.8/site-packages/jupyter_client/channels.py", line 315, in get_msg
    raise Empty
_queue.Empty

During handling of the above exception, another exception occurred:

Traceback (most recent call last):
  File "/opt/hostedtoolcache/Python/3.8.17/x64/lib/python3.8/site-packages/jupyter_cache/executors/utils.py", line 58, in single_nb_execution
    executenb(
  File "/opt/hostedtoolcache/Python/3.8.17/x64/lib/python3.8/site-packages/nbclient/client.py", line 1305, in execute
    return NotebookClient(nb=nb, resources=resources, km=km, **kwargs).execute()
  File "/opt/hostedtoolcache/Python/3.8.17/x64/lib/python3.8/site-packages/jupyter_core/utils/__init__.py", line 166, in wrapped
    return loop.run_until_complete(inner)
  File "/opt/hostedtoolcache/Python/3.8.17/x64/lib/python3.8/asyncio/base_events.py", line 616, in run_until_complete
    return future.result()
  File "/opt/hostedtoolcache/Python/3.8.17/x64/lib/python3.8/site-packages/nbclient/client.py", line 705, in async_execute
    await self.async_execute_cell(
  File "/opt/hostedtoolcache/Python/3.8.17/x64/lib/python3.8/site-packages/nbclient/client.py", line 1001, in async_execute_cell
    exec_reply = await self.task_poll_for_reply
  File "/opt/hostedtoolcache/Python/3.8.17/x64/lib/python3.8/site-packages/nbclient/client.py", line 802, in _async_poll_for_reply
    error_on_timeout_execute_reply = await self._async_handle_timeout(timeout, cell)
  File "/opt/hostedtoolcache/Python/3.8.17/x64/lib/python3.8/site-packages/nbclient/client.py", line 852, in _async_handle_timeout
    raise CellTimeoutError.error_from_timeout_and_cell(
nbclient.exceptions.CellTimeoutError: A cell timed out while it was being executed, after 30 seconds.
The message was: Cell execution timed out.
Here is a preview of the cell contents:
-------------------
im2d = ps.generators.blobs(shape=[500, 500])
im3d = ps.generators.blobs(shape=[500, 500, 500])

fig, ax = plt.subplots(1, 2, figsize=[12, 12]);
ax[0].imshow(im2d);
ax[0].axis(False);
ax[0].set_title('2D', fontdict={'fontsize': 18});
ax[1].imshow(im3d.take(indices=250, axis=2));
ax[1].axis(False);
ax[1].set_title('3D', fontdict={'fontsize': 18});
-------------------

